<?xml version="1.0"?>
<robot name="four_wheel_arm_robot">

  <material name="blue"><color rgba="0 0 0.8 1"/></material>
  <material name="black"><color rgba="0 0 0 1"/></material>
  <material name="grey"><color rgba="0.5 0.5 0.5 1"/></material>

  <link name="base_link">
    <visual>
      <geometry><box size="0.5 0.3 0.1"/></geometry>
      <material name="blue"/>
    </visual>
    <collision>
      <geometry><box size="0.5 0.3 0.1"/></geometry>
    </collision>
    <inertial>
      <mass value="5.0"/>
      <inertia ixx="0.04" ixy="0" ixz="0" iyy="0.1" iyz="0" izz="0.13"/>
    </inertial>
  </link>

  <link name="fl_wheel">
    <visual><geometry><cylinder length="0.05" radius="0.1"/></geometry><material name="black"/></visual>
    <collision><geometry><cylinder length="0.05" radius="0.1"/></geometry></collision>
    <inertial><mass value="0.5"/><inertia ixx="0.001" ixy="0" ixz="0" iyy="0.001" iyz="0" izz="0.001"/></inertial>
  </link>
  <joint name="fl_joint" type="continuous">
    <parent link="base_link"/><child link="fl_wheel"/>
    <origin xyz="0.2 0.175 0" rpy="1.5708 0 0"/><axis xyz="0 0 1"/>
  </joint>

  <link name="fr_wheel">
    <visual><geometry><cylinder length="0.05" radius="0.1"/></geometry><material name="black"/></visual>
    <collision><geometry><cylinder length="0.05" radius="0.1"/></geometry></collision>
    <inertial><mass value="0.5"/><inertia ixx="0.001" ixy="0" ixz="0" iyy="0.001" iyz="0" izz="0.001"/></inertial>
  </link>
  <joint name="fr_joint" type="continuous">
    <parent link="base_link"/><child link="fr_wheel"/>
    <origin xyz="0.2 -0.175 0" rpy="1.5708 0 0"/><axis xyz="0 0 1"/>
  </joint>

  <link name="bl_wheel">
    <visual><geometry><cylinder length="0.05" radius="0.1"/></geometry><material name="black"/></visual>
    <collision><geometry><cylinder length="0.05" radius="0.1"/></geometry></collision>
    <inertial><mass value="0.5"/><inertia ixx="0.001" ixy="0" ixz="0" iyy="0.001" iyz="0" izz="0.001"/></inertial>
  </link>
  <joint name="bl_joint" type="continuous">
    <parent link="base_link"/><child link="bl_wheel"/>
    <origin xyz="-0.2 0.175 0" rpy="1.5708 0 0"/><axis xyz="0 0 1"/>
  </joint>

  <link name="br_wheel">
    <visual><geometry><cylinder length="0.05" radius="0.1"/></geometry><material name="black"/></visual>
    <collision><geometry><cylinder length="0.05" radius="0.1"/></geometry></collision>
    <inertial><mass value="0.5"/><inertia ixx="0.001" ixy="0" ixz="0" iyy="0.001" iyz="0" izz="0.001"/></inertial>
  </link>
  <joint name="br_joint" type="continuous">
    <parent link="base_link"/><child link="br_wheel"/>
    <origin xyz="-0.2 -0.175 0" rpy="1.5708 0 0"/><axis xyz="0 0 1"/>
  </joint>

  <link name="arm_link">
    <visual>
      <geometry><box size="0.05 0.05 0.4"/></geometry>
      <material name="grey"/>
    </visual>
    <inertial><mass value="1.0"/><inertia ixx="0.01" ixy="0" ixz="0" iyy="0.01" iyz="0" izz="0.01"/></inertial>
  </link>
  <joint name="arm_extension_joint" type="prismatic">
    <parent link="base_link"/><child link="arm_link"/>
    <origin xyz="0 0 0.1" rpy="0 0 0"/>
    <axis xyz="0 0 1"/>
    <limit lower="0" upper="0.3" effort="50" velocity="1.0"/>
  </joint>

  <link name="gripper_finger">
    <visual>
      <origin xyz="0 0.05 0"/>
      <geometry><box size="0.02 0.1 0.02"/></geometry>
      <material name="black"/>
    </visual>
    <inertial><mass value="0.2"/><inertia ixx="0.001" ixy="0" ixz="0" iyy="0.001" iyz="0" izz="0.001"/></inertial>
  </link>
  <joint name="gripper_joint" type="revolute">
    <parent link="arm_link"/><child link="gripper_finger"/>
    <origin xyz="0 0 0.2" rpy="0 0 0"/>
    <axis xyz="0 0 1"/>
    <limit lower="-1.57" upper="1.57" effort="10" velocity="1.0"/>
  </joint>

</robot>